2023-01-27 23:42:37,965 - telegram.ext._application - INFO - Application started
2023-01-27 23:46:25,315 - telegram.ext._application - ERROR - No error handlers are registered, logging exception.
Traceback (most recent call last):
  File "/Library/Frameworks/Python.framework/Versions/3.9/lib/python3.9/site-packages/anyio/streams/tls.py", line 130, in _call_sslobject_method
    result = func(*args)
  File "/Library/Frameworks/Python.framework/Versions/3.9/lib/python3.9/ssl.py", line 888, in read
    v = self._sslobj.read(len)
ssl.SSLWantReadError: The operation did not complete (read) (_ssl.c:2622)

During handling of the above exception, another exception occurred:

Traceback (most recent call last):
  File "/Library/Frameworks/Python.framework/Versions/3.9/lib/python3.9/site-packages/httpcore/backends/asyncio.py", line 34, in read
    return await self._stream.receive(max_bytes=max_bytes)
  File "/Library/Frameworks/Python.framework/Versions/3.9/lib/python3.9/site-packages/anyio/streams/tls.py", line 195, in receive
    data = await self._call_sslobject_method(self._ssl_object.read, max_bytes)
  File "/Library/Frameworks/Python.framework/Versions/3.9/lib/python3.9/site-packages/anyio/streams/tls.py", line 137, in _call_sslobject_method
    data = await self.transport_stream.receive()
  File "/Library/Frameworks/Python.framework/Versions/3.9/lib/python3.9/site-packages/anyio/_backends/_asyncio.py", line 1265, in receive
    await self._protocol.read_event.wait()
  File "/Library/Frameworks/Python.framework/Versions/3.9/lib/python3.9/asyncio/locks.py", line 226, in wait
    await fut
asyncio.exceptions.CancelledError

During handling of the above exception, another exception occurred:

Traceback (most recent call last):
  File "/Library/Frameworks/Python.framework/Versions/3.9/lib/python3.9/site-packages/httpcore/_exceptions.py", line 10, in map_exceptions
    yield
  File "/Library/Frameworks/Python.framework/Versions/3.9/lib/python3.9/site-packages/httpcore/backends/asyncio.py", line 36, in read
    return b""
  File "/Library/Frameworks/Python.framework/Versions/3.9/lib/python3.9/site-packages/anyio/_core/_tasks.py", line 118, in __exit__
    raise TimeoutError
TimeoutError

During handling of the above exception, another exception occurred:

Traceback (most recent call last):
  File "/Library/Frameworks/Python.framework/Versions/3.9/lib/python3.9/site-packages/httpx/_transports/default.py", line 60, in map_httpcore_exceptions
    yield
  File "/Library/Frameworks/Python.framework/Versions/3.9/lib/python3.9/site-packages/httpx/_transports/default.py", line 353, in handle_async_request
    resp = await self._pool.handle_async_request(req)
  File "/Library/Frameworks/Python.framework/Versions/3.9/lib/python3.9/site-packages/httpcore/_async/connection_pool.py", line 253, in handle_async_request
    raise exc
  File "/Library/Frameworks/Python.framework/Versions/3.9/lib/python3.9/site-packages/httpcore/_async/connection_pool.py", line 237, in handle_async_request
    response = await connection.handle_async_request(request)
  File "/Library/Frameworks/Python.framework/Versions/3.9/lib/python3.9/site-packages/httpcore/_async/http_proxy.py", line 316, in handle_async_request
    return await self._connection.handle_async_request(request)
  File "/Library/Frameworks/Python.framework/Versions/3.9/lib/python3.9/site-packages/httpcore/_async/http11.py", line 112, in handle_async_request
    raise exc
  File "/Library/Frameworks/Python.framework/Versions/3.9/lib/python3.9/site-packages/httpcore/_async/http11.py", line 91, in handle_async_request
    ) = await self._receive_response_headers(**kwargs)
  File "/Library/Frameworks/Python.framework/Versions/3.9/lib/python3.9/site-packages/httpcore/_async/http11.py", line 155, in _receive_response_headers
    event = await self._receive_event(timeout=timeout)
  File "/Library/Frameworks/Python.framework/Versions/3.9/lib/python3.9/site-packages/httpcore/_async/http11.py", line 191, in _receive_event
    data = await self._network_stream.read(
  File "/Library/Frameworks/Python.framework/Versions/3.9/lib/python3.9/site-packages/httpcore/backends/asyncio.py", line 36, in read
    return b""
  File "/Library/Frameworks/Python.framework/Versions/3.9/lib/python3.9/contextlib.py", line 135, in __exit__
    self.gen.throw(type, value, traceback)
  File "/Library/Frameworks/Python.framework/Versions/3.9/lib/python3.9/site-packages/httpcore/_exceptions.py", line 14, in map_exceptions
    raise to_exc(exc)
httpcore.ReadTimeout

The above exception was the direct cause of the following exception:

Traceback (most recent call last):
  File "/Library/Frameworks/Python.framework/Versions/3.9/lib/python3.9/site-packages/telegram/request/_httpxrequest.py", line 183, in do_request
    res = await self._client.request(
  File "/Library/Frameworks/Python.framework/Versions/3.9/lib/python3.9/site-packages/httpx/_client.py", line 1533, in request
    return await self.send(request, auth=auth, follow_redirects=follow_redirects)
  File "/Library/Frameworks/Python.framework/Versions/3.9/lib/python3.9/site-packages/httpx/_client.py", line 1620, in send
    response = await self._send_handling_auth(
  File "/Library/Frameworks/Python.framework/Versions/3.9/lib/python3.9/site-packages/httpx/_client.py", line 1648, in _send_handling_auth
    response = await self._send_handling_redirects(
  File "/Library/Frameworks/Python.framework/Versions/3.9/lib/python3.9/site-packages/httpx/_client.py", line 1685, in _send_handling_redirects
    response = await self._send_single_request(request)
  File "/Library/Frameworks/Python.framework/Versions/3.9/lib/python3.9/site-packages/httpx/_client.py", line 1722, in _send_single_request
    response = await transport.handle_async_request(request)
  File "/Library/Frameworks/Python.framework/Versions/3.9/lib/python3.9/site-packages/httpx/_transports/default.py", line 353, in handle_async_request
    resp = await self._pool.handle_async_request(req)
  File "/Library/Frameworks/Python.framework/Versions/3.9/lib/python3.9/contextlib.py", line 135, in __exit__
    self.gen.throw(type, value, traceback)
  File "/Library/Frameworks/Python.framework/Versions/3.9/lib/python3.9/site-packages/httpx/_transports/default.py", line 77, in map_httpcore_exceptions
    raise mapped_exc(message) from exc
httpx.ReadTimeout

The above exception was the direct cause of the following exception:

Traceback (most recent call last):
  File "/Library/Frameworks/Python.framework/Versions/3.9/lib/python3.9/site-packages/telegram/ext/_application.py", line 1063, in process_update
    await coroutine
  File "/Library/Frameworks/Python.framework/Versions/3.9/lib/python3.9/site-packages/telegram/ext/_handler.py", line 141, in handle_update
    return await self.callback(update, context)
  File "/Users/xuanxiao/Desktop/vpn/telebot.py", line 15, in start
    await context.bot.send_message(chat_id=update.effective_chat.id, text=getWords())
  File "/Library/Frameworks/Python.framework/Versions/3.9/lib/python3.9/site-packages/telegram/ext/_extbot.py", line 2596, in send_message
    return await super().send_message(
  File "/Library/Frameworks/Python.framework/Versions/3.9/lib/python3.9/site-packages/telegram/_bot.py", line 334, in decorator
    result = await func(*args, **kwargs)  # skipcq: PYL-E1102
  File "/Library/Frameworks/Python.framework/Versions/3.9/lib/python3.9/site-packages/telegram/_bot.py", line 767, in send_message
    return await self._send_message(
  File "/Library/Frameworks/Python.framework/Versions/3.9/lib/python3.9/site-packages/telegram/ext/_extbot.py", line 488, in _send_message
    result = await super()._send_message(
  File "/Library/Frameworks/Python.framework/Versions/3.9/lib/python3.9/site-packages/telegram/_bot.py", line 515, in _send_message
    result = await self._post(
  File "/Library/Frameworks/Python.framework/Versions/3.9/lib/python3.9/site-packages/telegram/_bot.py", line 422, in _post
    return await self._do_post(
  File "/Library/Frameworks/Python.framework/Versions/3.9/lib/python3.9/site-packages/telegram/ext/_extbot.py", line 306, in _do_post
    return await super()._do_post(
  File "/Library/Frameworks/Python.framework/Versions/3.9/lib/python3.9/site-packages/telegram/_bot.py", line 453, in _do_post
    return await request.post(
  File "/Library/Frameworks/Python.framework/Versions/3.9/lib/python3.9/site-packages/telegram/request/_baserequest.py", line 165, in post
    result = await self._request_wrapper(
  File "/Library/Frameworks/Python.framework/Versions/3.9/lib/python3.9/site-packages/telegram/request/_baserequest.py", line 288, in _request_wrapper
    raise exc
  File "/Library/Frameworks/Python.framework/Versions/3.9/lib/python3.9/site-packages/telegram/request/_baserequest.py", line 274, in _request_wrapper
    code, payload = await self.do_request(
  File "/Library/Frameworks/Python.framework/Versions/3.9/lib/python3.9/site-packages/telegram/request/_httpxrequest.py", line 200, in do_request
    raise TimedOut from err
telegram.error.TimedOut: Timed out
2023-01-27 23:46:32,335 - telegram.ext._updater - ERROR - Error while getting Updates: httpx HTTPError: Server disconnected without sending a response.
2023-01-27 23:46:32,336 - telegram.ext._application - ERROR - No error handlers are registered, logging exception.
Traceback (most recent call last):
  File "/Library/Frameworks/Python.framework/Versions/3.9/lib/python3.9/site-packages/httpx/_transports/default.py", line 60, in map_httpcore_exceptions
    yield
  File "/Library/Frameworks/Python.framework/Versions/3.9/lib/python3.9/site-packages/httpx/_transports/default.py", line 353, in handle_async_request
    resp = await self._pool.handle_async_request(req)
  File "/Library/Frameworks/Python.framework/Versions/3.9/lib/python3.9/site-packages/httpcore/_async/connection_pool.py", line 253, in handle_async_request
    raise exc
  File "/Library/Frameworks/Python.framework/Versions/3.9/lib/python3.9/site-packages/httpcore/_async/connection_pool.py", line 237, in handle_async_request
    response = await connection.handle_async_request(request)
  File "/Library/Frameworks/Python.framework/Versions/3.9/lib/python3.9/site-packages/httpcore/_async/http_proxy.py", line 316, in handle_async_request
    return await self._connection.handle_async_request(request)
  File "/Library/Frameworks/Python.framework/Versions/3.9/lib/python3.9/site-packages/httpcore/_async/http11.py", line 112, in handle_async_request
    raise exc
  File "/Library/Frameworks/Python.framework/Versions/3.9/lib/python3.9/site-packages/httpcore/_async/http11.py", line 91, in handle_async_request
    ) = await self._receive_response_headers(**kwargs)
  File "/Library/Frameworks/Python.framework/Versions/3.9/lib/python3.9/site-packages/httpcore/_async/http11.py", line 155, in _receive_response_headers
    event = await self._receive_event(timeout=timeout)
  File "/Library/Frameworks/Python.framework/Versions/3.9/lib/python3.9/site-packages/httpcore/_async/http11.py", line 205, in _receive_event
    raise RemoteProtocolError(msg)
httpcore.RemoteProtocolError: Server disconnected without sending a response.

The above exception was the direct cause of the following exception:

Traceback (most recent call last):
  File "/Library/Frameworks/Python.framework/Versions/3.9/lib/python3.9/site-packages/telegram/request/_httpxrequest.py", line 183, in do_request
    res = await self._client.request(
  File "/Library/Frameworks/Python.framework/Versions/3.9/lib/python3.9/site-packages/httpx/_client.py", line 1533, in request
    return await self.send(request, auth=auth, follow_redirects=follow_redirects)
  File "/Library/Frameworks/Python.framework/Versions/3.9/lib/python3.9/site-packages/httpx/_client.py", line 1620, in send
    response = await self._send_handling_auth(
  File "/Library/Frameworks/Python.framework/Versions/3.9/lib/python3.9/site-packages/httpx/_client.py", line 1648, in _send_handling_auth
    response = await self._send_handling_redirects(
  File "/Library/Frameworks/Python.framework/Versions/3.9/lib/python3.9/site-packages/httpx/_client.py", line 1685, in _send_handling_redirects
    response = await self._send_single_request(request)
  File "/Library/Frameworks/Python.framework/Versions/3.9/lib/python3.9/site-packages/httpx/_client.py", line 1722, in _send_single_request
    response = await transport.handle_async_request(request)
  File "/Library/Frameworks/Python.framework/Versions/3.9/lib/python3.9/site-packages/httpx/_transports/default.py", line 353, in handle_async_request
    resp = await self._pool.handle_async_request(req)
  File "/Library/Frameworks/Python.framework/Versions/3.9/lib/python3.9/contextlib.py", line 135, in __exit__
    self.gen.throw(type, value, traceback)
  File "/Library/Frameworks/Python.framework/Versions/3.9/lib/python3.9/site-packages/httpx/_transports/default.py", line 77, in map_httpcore_exceptions
    raise mapped_exc(message) from exc
httpx.RemoteProtocolError: Server disconnected without sending a response.

The above exception was the direct cause of the following exception:

Traceback (most recent call last):
  File "/Library/Frameworks/Python.framework/Versions/3.9/lib/python3.9/site-packages/telegram/ext/_updater.py", line 600, in _network_loop_retry
    if not await action_cb():
  File "/Library/Frameworks/Python.framework/Versions/3.9/lib/python3.9/site-packages/telegram/ext/_updater.py", line 327, in polling_action_cb
    raise exc
  File "/Library/Frameworks/Python.framework/Versions/3.9/lib/python3.9/site-packages/telegram/ext/_updater.py", line 312, in polling_action_cb
    updates = await self.bot.get_updates(
  File "/Library/Frameworks/Python.framework/Versions/3.9/lib/python3.9/site-packages/telegram/ext/_extbot.py", line 524, in get_updates
    updates = await super().get_updates(
  File "/Library/Frameworks/Python.framework/Versions/3.9/lib/python3.9/site-packages/telegram/_bot.py", line 334, in decorator
    result = await func(*args, **kwargs)  # skipcq: PYL-E1102
  File "/Library/Frameworks/Python.framework/Versions/3.9/lib/python3.9/site-packages/telegram/_bot.py", line 3584, in get_updates
    await self._post(
  File "/Library/Frameworks/Python.framework/Versions/3.9/lib/python3.9/site-packages/telegram/_bot.py", line 422, in _post
    return await self._do_post(
  File "/Library/Frameworks/Python.framework/Versions/3.9/lib/python3.9/site-packages/telegram/ext/_extbot.py", line 306, in _do_post
    return await super()._do_post(
  File "/Library/Frameworks/Python.framework/Versions/3.9/lib/python3.9/site-packages/telegram/_bot.py", line 453, in _do_post
    return await request.post(
  File "/Library/Frameworks/Python.framework/Versions/3.9/lib/python3.9/site-packages/telegram/request/_baserequest.py", line 165, in post
    result = await self._request_wrapper(
  File "/Library/Frameworks/Python.framework/Versions/3.9/lib/python3.9/site-packages/telegram/request/_baserequest.py", line 288, in _request_wrapper
    raise exc
  File "/Library/Frameworks/Python.framework/Versions/3.9/lib/python3.9/site-packages/telegram/request/_baserequest.py", line 274, in _request_wrapper
    code, payload = await self.do_request(
  File "/Library/Frameworks/Python.framework/Versions/3.9/lib/python3.9/site-packages/telegram/request/_httpxrequest.py", line 204, in do_request
    raise NetworkError(f"httpx HTTPError: {err}") from err
telegram.error.NetworkError: httpx HTTPError: Server disconnected without sending a response.
2023-01-27 23:48:55,332 - telegram.ext._updater - ERROR - Error while getting Updates: httpx HTTPError: Server disconnected without sending a response.
2023-01-27 23:48:55,332 - telegram.ext._application - ERROR - No error handlers are registered, logging exception.
Traceback (most recent call last):
  File "/Library/Frameworks/Python.framework/Versions/3.9/lib/python3.9/site-packages/httpx/_transports/default.py", line 60, in map_httpcore_exceptions
    yield
  File "/Library/Frameworks/Python.framework/Versions/3.9/lib/python3.9/site-packages/httpx/_transports/default.py", line 353, in handle_async_request
    resp = await self._pool.handle_async_request(req)
  File "/Library/Frameworks/Python.framework/Versions/3.9/lib/python3.9/site-packages/httpcore/_async/connection_pool.py", line 253, in handle_async_request
    raise exc
  File "/Library/Frameworks/Python.framework/Versions/3.9/lib/python3.9/site-packages/httpcore/_async/connection_pool.py", line 237, in handle_async_request
    response = await connection.handle_async_request(request)
  File "/Library/Frameworks/Python.framework/Versions/3.9/lib/python3.9/site-packages/httpcore/_async/http_proxy.py", line 316, in handle_async_request
    return await self._connection.handle_async_request(request)
  File "/Library/Frameworks/Python.framework/Versions/3.9/lib/python3.9/site-packages/httpcore/_async/http11.py", line 112, in handle_async_request
    raise exc
  File "/Library/Frameworks/Python.framework/Versions/3.9/lib/python3.9/site-packages/httpcore/_async/http11.py", line 91, in handle_async_request
    ) = await self._receive_response_headers(**kwargs)
  File "/Library/Frameworks/Python.framework/Versions/3.9/lib/python3.9/site-packages/httpcore/_async/http11.py", line 155, in _receive_response_headers
    event = await self._receive_event(timeout=timeout)
  File "/Library/Frameworks/Python.framework/Versions/3.9/lib/python3.9/site-packages/httpcore/_async/http11.py", line 205, in _receive_event
    raise RemoteProtocolError(msg)
httpcore.RemoteProtocolError: Server disconnected without sending a response.

The above exception was the direct cause of the following exception:

Traceback (most recent call last):
  File "/Library/Frameworks/Python.framework/Versions/3.9/lib/python3.9/site-packages/telegram/request/_httpxrequest.py", line 183, in do_request
    res = await self._client.request(
  File "/Library/Frameworks/Python.framework/Versions/3.9/lib/python3.9/site-packages/httpx/_client.py", line 1533, in request
    return await self.send(request, auth=auth, follow_redirects=follow_redirects)
  File "/Library/Frameworks/Python.framework/Versions/3.9/lib/python3.9/site-packages/httpx/_client.py", line 1620, in send
    response = await self._send_handling_auth(
  File "/Library/Frameworks/Python.framework/Versions/3.9/lib/python3.9/site-packages/httpx/_client.py", line 1648, in _send_handling_auth
    response = await self._send_handling_redirects(
  File "/Library/Frameworks/Python.framework/Versions/3.9/lib/python3.9/site-packages/httpx/_client.py", line 1685, in _send_handling_redirects
    response = await self._send_single_request(request)
  File "/Library/Frameworks/Python.framework/Versions/3.9/lib/python3.9/site-packages/httpx/_client.py", line 1722, in _send_single_request
    response = await transport.handle_async_request(request)
  File "/Library/Frameworks/Python.framework/Versions/3.9/lib/python3.9/site-packages/httpx/_transports/default.py", line 353, in handle_async_request
    resp = await self._pool.handle_async_request(req)
  File "/Library/Frameworks/Python.framework/Versions/3.9/lib/python3.9/contextlib.py", line 135, in __exit__
    self.gen.throw(type, value, traceback)
  File "/Library/Frameworks/Python.framework/Versions/3.9/lib/python3.9/site-packages/httpx/_transports/default.py", line 77, in map_httpcore_exceptions
    raise mapped_exc(message) from exc
httpx.RemoteProtocolError: Server disconnected without sending a response.

The above exception was the direct cause of the following exception:

Traceback (most recent call last):
  File "/Library/Frameworks/Python.framework/Versions/3.9/lib/python3.9/site-packages/telegram/ext/_updater.py", line 600, in _network_loop_retry
    if not await action_cb():
  File "/Library/Frameworks/Python.framework/Versions/3.9/lib/python3.9/site-packages/telegram/ext/_updater.py", line 327, in polling_action_cb
    raise exc
  File "/Library/Frameworks/Python.framework/Versions/3.9/lib/python3.9/site-packages/telegram/ext/_updater.py", line 312, in polling_action_cb
    updates = await self.bot.get_updates(
  File "/Library/Frameworks/Python.framework/Versions/3.9/lib/python3.9/site-packages/telegram/ext/_extbot.py", line 524, in get_updates
    updates = await super().get_updates(
  File "/Library/Frameworks/Python.framework/Versions/3.9/lib/python3.9/site-packages/telegram/_bot.py", line 334, in decorator
    result = await func(*args, **kwargs)  # skipcq: PYL-E1102
  File "/Library/Frameworks/Python.framework/Versions/3.9/lib/python3.9/site-packages/telegram/_bot.py", line 3584, in get_updates
    await self._post(
  File "/Library/Frameworks/Python.framework/Versions/3.9/lib/python3.9/site-packages/telegram/_bot.py", line 422, in _post
    return await self._do_post(
  File "/Library/Frameworks/Python.framework/Versions/3.9/lib/python3.9/site-packages/telegram/ext/_extbot.py", line 306, in _do_post
    return await super()._do_post(
  File "/Library/Frameworks/Python.framework/Versions/3.9/lib/python3.9/site-packages/telegram/_bot.py", line 453, in _do_post
    return await request.post(
  File "/Library/Frameworks/Python.framework/Versions/3.9/lib/python3.9/site-packages/telegram/request/_baserequest.py", line 165, in post
    result = await self._request_wrapper(
  File "/Library/Frameworks/Python.framework/Versions/3.9/lib/python3.9/site-packages/telegram/request/_baserequest.py", line 288, in _request_wrapper
    raise exc
  File "/Library/Frameworks/Python.framework/Versions/3.9/lib/python3.9/site-packages/telegram/request/_baserequest.py", line 274, in _request_wrapper
    code, payload = await self.do_request(
  File "/Library/Frameworks/Python.framework/Versions/3.9/lib/python3.9/site-packages/telegram/request/_httpxrequest.py", line 204, in do_request
    raise NetworkError(f"httpx HTTPError: {err}") from err
telegram.error.NetworkError: httpx HTTPError: Server disconnected without sending a response.
